Workbook

Sheet Planilha1
A1: REL 06GQ10 | D1: AVALIAÇÃO DOS CERTIFICADOS DE CALIBRAÇÃO DE DATA LOGGERS - TESTO 174H
A2: Versão: 00 Data: (data do relatório)
A5: INSTRUMENTO | C5: Marca | F5: ESPECIFICAÇÕES / CRITÉRIOS DE ACEITAÇÃO | K5: TEMPERATURA | S5: Legenda:
C6: TESTO | K6: RESOLUÇÃO | M6: 0.1 | N6: UNIDADE | P6: °C | Q6: DMA | R6: 0.5 | S6: DMA: Desvio Máximo Aceitável
C7: Modelo | K7: UMIDADE | S7: Inc.: Incerteza de Medição
C8: 174H | K8: RESOLUÇÃO | M8: 0.1 | N8: UNIDADE | P8: % | Q8: DMA | R8: 5
F9: Temperatura | P9: Umidade
D10: Ponto de calibração: | G10: -20,0°C | I10: 0,0°C | K10: 15,0°C | M10: 60,0°C | O10: Temperatura | P10: 10,0 %U.R. | S10: 50,0 %U.R. | V10: 90,0 %U.R. | Y10: Umidade
A11: N° Série | B11: TAG | C11: Calibrado em | D11: Validade | E11: Certificado | F11: Inc. | G11: Erro | H11: Resultado | I11: Erro | J11: Resultado | K11: Erro | L11: Resultado | M11: Erro | N11: Resultado | O11: RESULTADO | P11: Inc. | Q11: Erro | R11: Resultado | S11: Inc. | T11: Erro | U11: Resultado | V11: Inc. | W11: Erro | X11: Resultado | Y11: RESULTADO
A12: 37323285 | B12: DLH-0002 | C12: 45855 | D12: 46220 | E12: 605514 | F12: 0.2 | G12: 0.09 | H12: 0.29 | I12: 0.09 | J12: 0.29 | K12: -0.01 | L12: 0.21 | M12: -0.11 | N12: 0.31 | O12: =IF(OR(INDEX([1]Relação_Calibrações_Localização!$F$8:$F$259,MATCH(B12,[1]Relação_Calibrações_Localização!$B$8:$B$259,0))="PERDIDO",INDEX([1]Relação_Calibrações_Localização!F9:F259,MATCH(B12,[1]Relação_Calibrações_Localização!$B$8:$B$259,0))="NÃO LOCALIZADO"),"PERDIDO", IF(OR(G12="",I12="",K12="",M12=""),"INDETERMINADO",IF(MAX(H12,J12,L12,N12)<=0.5,"APROVADO","REPROVADO"))) -> APROVADO | P12: 0.4 | Q12: 2.8 | R12: 3.2 | S12: 1 | T12: 0.3 | U12: 1.3 | V12: 1.5 | W12: -0.4 | X12: 1.9 | Y12: =IF(OR(INDEX([1]Relação_Calibrações_Localização!$F$8:$F$259,MATCH(B12,[1]Relação_Calibrações_Localização!$B$8:$B$259,0))="PERDIDO",INDEX([1]Relação_Calibrações_Localização!F9:F259,MATCH(B12,[1]Relação_Calibrações_Localização!$B$8:$B$259,0))="NÃO LOCALIZADO"),"PERDIDO", IF(OR(Q12="",T12="",W12=""),"INDETERMINADO",IF(MAX(R12,U12,X12)<=5,"APROVADO","REPROVADO"))) -> APROVADO
A13: 37323286 | B13: DLH-0003 | C13: 45855 | D13: 46220 | E13: 605477 | F13: 0.2 | G13: -0.21 | H13: 0.41 | I13: -0.11 | J13: 0.31 | K13: -0.11 | L13: 0.31 | M13: 0.09 | N13: 0.29 | O13: =IF(OR(INDEX([1]Relação_Calibrações_Localização!$F$8:$F$259,MATCH(B13,[1]Relação_Calibrações_Localização!$B$8:$B$259,0))="PERDIDO",INDEX([1]Relação_Calibrações_Localização!F10:F260,MATCH(B13,[1]Relação_Calibrações_Localização!$B$8:$B$259,0))="NÃO LOCALIZADO"),"PERDIDO", IF(OR(G13="",I13="",K13="",M13=""),"INDETERMINADO",IF(MAX(H13,J13,L13,N13)<=0.5,"APROVADO","REPROVADO"))) -> APROVADO | P13: 0.4 | Q13: 3 | R13: 3.4 | S13: 1 | T13: 2.5 | U13: 3.5 | V13: 1.5 | W13: 2.9 | X13: 4.4 | Y13: =IF(OR(INDEX([1]Relação_Calibrações_Localização!$F$8:$F$259,MATCH(B13,[1]Relação_Calibrações_Localização!$B$8:$B$259,0))="PERDIDO",INDEX([1]Relação_Calibrações_Localização!F10:F260,MATCH(B13,[1]Relação_Calibrações_Localização!$B$8:$B$259,0))="NÃO LOCALIZADO"),"PERDIDO", IF(OR(Q13="",T13="",W13=""),"INDETERMINADO",IF(MAX(R13,U13,X13)<=5,"APROVADO","REPROVADO"))) -> APROVADO
A14: 37326170 | B14: DLH-0004 | C14: 45855 | D14: 46220 | E14: 605462 | F14: 0.2 | G14: -0.11 | H14: 0.31 | I14: -0.11 | J14: 0.31 | K14: -0.01 | L14: 0.21 | M14: 0.19 | N14: 0.39 | O14: =IF(OR(INDEX([1]Relação_Calibrações_Localização!$F$8:$F$259,MATCH(B14,[1]Relação_Calibrações_Localização!$B$8:$B$259,0))="PERDIDO",INDEX([1]Relação_Calibrações_Localização!F11:F261,MATCH(B14,[1]Relação_Calibrações_Localização!$B$8:$B$259,0))="NÃO LOCALIZADO"),"PERDIDO", IF(OR(G14="",I14="",K14="",M14=""),"INDETERMINADO",IF(MAX(H14,J14,L14,N14)<=0.5,"APROVADO","REPROVADO"))) -> APROVADO | P14: 0.4 | Q14: 2.8 | R14: 3.2 | S14: 1 | T14: 0.5 | U14: 1.5 | V14: 1.5 | W14: 1.1 | X14: 2.6 | Y14: =IF(OR(INDEX([1]Relação_Calibrações_Localização!$F$8:$F$259,MATCH(B14,[1]Relação_Calibrações_Localização!$B$8:$B$259,0))="PERDIDO",INDEX([1]Relação_Calibrações_Localização!F11:F261,MATCH(B14,[1]Relação_Calibrações_Localização!$B$8:$B$259,0))="NÃO LOCALIZADO"),"PERDIDO", IF(OR(Q14="",T14="",W14=""),"INDETERMINADO",IF(MAX(R14,U14,X14)<=5,"APROVADO","REPROVADO"))) -> APROVADO
A15: 37326227 | B15: DLH-0006 | C15: 45855 | D15: 46220 | E15: 605420 | F15: 0.2 | G15: -0.11 | H15: 0.31 | I15: -0.01 | J15: 0.21 | K15: -0.01 | L15: 0.21 | M15: 0.09 | N15: 0.29 | O15: =IF(OR(INDEX([1]Relação_Calibrações_Localização!$F$8:$F$259,MATCH(B15,[1]Relação_Calibrações_Localização!$B$8:$B$259,0))="PERDIDO",INDEX([1]Relação_Calibrações_Localização!F13:F263,MATCH(B15,[1]Relação_Calibrações_Localização!$B$8:$B$259,0))="NÃO LOCALIZADO"),"PERDIDO", IF(OR(G15="",I15="",K15="",M15=""),"INDETERMINADO",IF(MAX(H15,J15,L15,N15)<=0.5,"APROVADO","REPROVADO"))) -> APROVADO | P15: 0.4 | Q15: 2.8 | R15: 3.2 | S15: 1 | T15: 3.6 | U15: 4.6 | V15: 1.5 | W15: 1.5 | X15: 3 | Y15: =IF(OR(INDEX([1]Relação_Calibrações_Localização!$F$8:$F$259,MATCH(B15,[1]Relação_Calibrações_Localização!$B$8:$B$259,0))="PERDIDO",INDEX([1]Relação_Calibrações_Localização!F13:F263,MATCH(B15,[1]Relação_Calibrações_Localização!$B$8:$B$259,0))="NÃO LOCALIZADO"),"PERDIDO", IF(OR(Q15="",T15="",W15=""),"INDETERMINADO",IF(MAX(R15,U15,X15)<=5,"APROVADO","REPROVADO"))) -> APROVADO
A16: 37331967 | B16: DLH-0007 | C16: 45855 | D16: 46220 | E16: 605430 | F16: 0.2 | G16: -0.21 | H16: 0.41 | I16: -0.21 | J16: 0.41 | K16: -0.11 | L16: 0.31 | M16: -0.01 | N16: 0.21 | O16: =IF(OR(INDEX([1]Relação_Calibrações_Localização!$F$8:$F$259,MATCH(B16,[1]Relação_Calibrações_Localização!$B$8:$B$259,0))="PERDIDO",INDEX([1]Relação_Calibrações_Localização!F14:F264,MATCH(B16,[1]Relação_Calibrações_Localização!$B$8:$B$259,0))="NÃO LOCALIZADO"),"PERDIDO", IF(OR(G16="",I16="",K16="",M16=""),"INDETERMINADO",IF(MAX(H16,J16,L16,N16)<=0.5,"APROVADO","REPROVADO"))) -> APROVADO | P16: 0.4 | Q16: 4.9 | R16: 5.3 | S16: 1 | T16: 4.2 | U16: 5.2 | V16: 1.5 | W16: 3.5 | X16: 5 | Y16: =IF(OR(INDEX([1]Relação_Calibrações_Localização!$F$8:$F$259,MATCH(B16,[1]Relação_Calibrações_Localização!$B$8:$B$259,0))="PERDIDO",INDEX([1]Relação_Calibrações_Localização!F14:F264,MATCH(B16,[1]Relação_Calibrações_Localização!$B$8:$B$259,0))="NÃO LOCALIZADO"),"PERDIDO", IF(OR(Q16="",T16="",W16=""),"INDETERMINADO",IF(MAX(R16,U16,X16)<=5,"APROVADO","REPROVADO"))) -> REPROVADO
A17: 37331975 | B17: DLH-0008 | C17: 45855 | D17: 46220 | E17: 605444 | F17: 0.2 | G17: -0.21 | H17: 0.41 | I17: -0.21 | J17: 0.41 | K17: -0.11 | L17: 0.31 | M17: -0.01 | N17: 0.21 | O17: =IF(OR(INDEX([1]Relação_Calibrações_Localização!$F$8:$F$259,MATCH(B17,[1]Relação_Calibrações_Localização!$B$8:$B$259,0))="PERDIDO",INDEX([1]Relação_Calibrações_Localização!F15:F265,MATCH(B17,[1]Relação_Calibrações_Localização!$B$8:$B$259,0))="NÃO LOCALIZADO"),"PERDIDO", IF(OR(G17="",I17="",K17="",M17=""),"INDETERMINADO",IF(MAX(H17,J17,L17,N17)<=0.5,"APROVADO","REPROVADO"))) -> APROVADO | P17: 0.4 | Q17: 3.6 | R17: 4 | S17: 1 | T17: 3.3 | U17: 4.3 | V17: 1.5 | W17: 1.9 | X17: 3.4 | Y17: =IF(OR(INDEX([1]Relação_Calibrações_Localização!$F$8:$F$259,MATCH(B17,[1]Relação_Calibrações_Localização!$B$8:$B$259,0))="PERDIDO",INDEX([1]Relação_Calibrações_Localização!F15:F265,MATCH(B17,[1]Relação_Calibrações_Localização!$B$8:$B$259,0))="NÃO LOCALIZADO"),"PERDIDO", IF(OR(Q17="",T17="",W17=""),"INDETERMINADO",IF(MAX(R17,U17,X17)<=5,"APROVADO","REPROVADO"))) -> APROVADO
A18: 37332212 | B18: DLH-0011 | C18: 45855 | D18: 46220 | E18: 605481 | F18: 0.2 | G18: -0.01 | H18: 0.21 | I18: 0.09 | J18: 0.29 | K18: 0.09 | L18: 0.29 | M18: 0.19 | N18: 0.39 | O18: =IF(OR(INDEX([1]Relação_Calibrações_Localização!$F$8:$F$259,MATCH(B18,[1]Relação_Calibrações_Localização!$B$8:$B$259,0))="PERDIDO",INDEX([1]Relação_Calibrações_Localização!F18:F268,MATCH(B18,[1]Relação_Calibrações_Localização!$B$8:$B$259,0))="NÃO LOCALIZADO"),"PERDIDO", IF(OR(G18="",I18="",K18="",M18=""),"INDETERMINADO",IF(MAX(H18,J18,L18,N18)<=0.5,"APROVADO","REPROVADO"))) -> APROVADO | P18: 0.4 | Q18: 2 | R18: 2.4 | S18: 1 | T18: 1.8 | U18: 2.8 | V18: 1.5 | W18: -0.5 | X18: 2 | Y18: =IF(OR(INDEX([1]Relação_Calibrações_Localização!$F$8:$F$259,MATCH(B18,[1]Relação_Calibrações_Localização!$B$8:$B$259,0))="PERDIDO",INDEX([1]Relação_Calibrações_Localização!F18:F268,MATCH(B18,[1]Relação_Calibrações_Localização!$B$8:$B$259,0))="NÃO LOCALIZADO"),"PERDIDO", IF(OR(Q18="",T18="",W18=""),"INDETERMINADO",IF(MAX(R18,U18,X18)<=5,"APROVADO","REPROVADO"))) -> APROVADO
A19: 37332214 | B19: DLH-0012 | C19: 45855 | D19: 46220 | E19: 605529 | F19: 0.2 | G19: 0.09 | H19: 0.29 | I19: 0.09 | J19: 0.29 | K19: -0.01 | L19: 0.21 | M19: -0.21 | N19: 0.41 | O19: =IF(OR(INDEX([1]Relação_Calibrações_Localização!$F$8:$F$259,MATCH(B19,[1]Relação_Calibrações_Localização!$B$8:$B$259,0))="PERDIDO",INDEX([1]Relação_Calibrações_Localização!F19:F269,MATCH(B19,[1]Relação_Calibrações_Localização!$B$8:$B$259,0))="NÃO LOCALIZADO"),"PERDIDO", IF(OR(G19="",I19="",K19="",M19=""),"INDETERMINADO",IF(MAX(H19,J19,L19,N19)<=0.5,"APROVADO","REPROVADO"))) -> APROVADO | P19: 0.4 | Q19: 2.6 | R19: 3 | S19: 1 | T19: 2.3 | U19: 3.3 | V19: 1.5 | W19: 1.2 | X19: 2.7 | Y19: =IF(OR(INDEX([1]Relação_Calibrações_Localização!$F$8:$F$259,MATCH(B19,[1]Relação_Calibrações_Localização!$B$8:$B$259,0))="PERDIDO",INDEX([1]Relação_Calibrações_Localização!F19:F269,MATCH(B19,[1]Relação_Calibrações_Localização!$B$8:$B$259,0))="NÃO LOCALIZADO"),"PERDIDO", IF(OR(Q19="",T19="",W19=""),"INDETERMINADO",IF(MAX(R19,U19,X19)<=5,"APROVADO","REPROVADO"))) -> APROVADO
A20: 37332216 | B20: DLH-0014 | C20: 45855 | D20: 46220 | E20: 605432 | F20: 0.2 | G20: 0.19 | H20: 0.39 | I20: 0.19 | J20: 0.39 | K20: 0.09 | L20: 0.29 | M20: -0.01 | N20: 0.21 | O20: APROVADO | P20: 0.4 | Q20: 3 | R20: 3.4 | S20: 1 | T20: 2.6 | U20: 3.6 | V20: 1.5 | W20: 0.2 | X20: 1.7 | Y20: =IF(OR(INDEX([1]Relação_Calibrações_Localização!$F$8:$F$259,MATCH(B20,[1]Relação_Calibrações_Localização!$B$8:$B$259,0))="PERDIDO",INDEX([1]Relação_Calibrações_Localização!F21:F271,MATCH(B20,[1]Relação_Calibrações_Localização!$B$8:$B$259,0))="NÃO LOCALIZADO"),"PERDIDO", IF(OR(Q20="",T20="",W20=""),"INDETERMINADO",IF(MAX(R20,U20,X20)<=5,"APROVADO","REPROVADO"))) -> APROVADO
A21: 37332217 | B21: DLH-0015 | C21: 45855 | D21: 46220 | E21: 605422 | F21: 0.2 | G21: -0.21 | H21: 0.41 | I21: -0.11 | J21: 0.31 | K21: -0.11 | L21: 0.31 | M21: 0.09 | N21: 0.29 | O21: =IF(OR(INDEX([1]Relação_Calibrações_Localização!$F$8:$F$259,MATCH(B21,[1]Relação_Calibrações_Localização!$B$8:$B$259,0))="PERDIDO",INDEX([1]Relação_Calibrações_Localização!F22:F272,MATCH(B21,[1]Relação_Calibrações_Localização!$B$8:$B$259,0))="NÃO LOCALIZADO"),"PERDIDO", IF(OR(G21="",I21="",K21="",M21=""),"INDETERMINADO",IF(MAX(H21,J21,L21,N21)<=0.5,"APROVADO","REPROVADO"))) -> APROVADO | P21: 0.4 | Q21: 3.9 | R21: 4.3 | S21: 1 | T21: 3.3 | U21: 4.3 | V21: 1.5 | W21: 1.5 | X21: 3 | Y21: =IF(OR(INDEX([1]Relação_Calibrações_Localização!$F$8:$F$259,MATCH(B21,[1]Relação_Calibrações_Localização!$B$8:$B$259,0))="PERDIDO",INDEX([1]Relação_Calibrações_Localização!F22:F272,MATCH(B21,[1]Relação_Calibrações_Localização!$B$8:$B$259,0))="NÃO LOCALIZADO"),"PERDIDO", IF(OR(Q21="",T21="",W21=""),"INDETERMINADO",IF(MAX(R21,U21,X21)<=5,"APROVADO","REPROVADO"))) -> APROVADO
A22: 37332224 | B22: DLH-0017 | C22: 45855 | D22: 46220 | E22: 605499 | F22: 0.2 | G22: 0.09 | H22: 0.29 | I22: 0.09 | J22: 0.29 | K22: 0.09 | L22: 0.29 | M22: 0.19 | N22: 0.39 | O22: =IF(OR(INDEX([1]Relação_Calibrações_Localização!$F$8:$F$259,MATCH(B22,[1]Relação_Calibrações_Localização!$B$8:$B$259,0))="PERDIDO",INDEX([1]Relação_Calibrações_Localização!F24:F274,MATCH(B22,[1]Relação_Calibrações_Localização!$B$8:$B$259,0))="NÃO LOCALIZADO"),"PERDIDO", IF(OR(G22="",I22="",K22="",M22=""),"INDETERMINADO",IF(MAX(H22,J22,L22,N22)<=0.5,"APROVADO","REPROVADO"))) -> APROVADO | P22: 0.4 | Q22: 2.6 | R22: 3 | S22: 1 | T22: 2.5 | U22: 3.5 | V22: 1.5 | W22: 0.9 | X22: 2.4 | Y22: =IF(OR(INDEX([1]Relação_Calibrações_Localização!$F$8:$F$259,MATCH(B22,[1]Relação_Calibrações_Localização!$B$8:$B$259,0))="PERDIDO",INDEX([1]Relação_Calibrações_Localização!F24:F274,MATCH(B22,[1]Relação_Calibrações_Localização!$B$8:$B$259,0))="NÃO LOCALIZADO"),"PERDIDO", IF(OR(Q22="",T22="",W22=""),"INDETERMINADO",IF(MAX(R22,U22,X22)<=5,"APROVADO","REPROVADO"))) -> APROVADO
A23: 37332227 | B23: DLH-0018 | C23: 45855 | D23: 46220 | E23: 605440 | F23: 0.2 | G23: -0.21 | H23: 0.41 | I23: 0.09 | J23: 0.29 | K23: 0.09 | L23: 0.29 | M23: -0.11 | N23: 0.31 | O23: =IF(OR(INDEX([1]Relação_Calibrações_Localização!$F$8:$F$259,MATCH(B23,[1]Relação_Calibrações_Localização!$B$8:$B$259,0))="PERDIDO",INDEX([1]Relação_Calibrações_Localização!F25:F275,MATCH(B23,[1]Relação_Calibrações_Localização!$B$8:$B$259,0))="NÃO LOCALIZADO"),"PERDIDO", IF(OR(G23="",I23="",K23="",M23=""),"INDETERMINADO",IF(MAX(H23,J23,L23,N23)<=0.5,"APROVADO","REPROVADO"))) -> APROVADO | P23: 0.4 | Q23: 3.6 | R23: 4 | S23: 1 | T23: 3.7 | U23: 4.7 | V23: 1.5 | W23: 2.6 | X23: 4.1 | Y23: =IF(OR(INDEX([1]Relação_Calibrações_Localização!$F$8:$F$259,MATCH(B23,[1]Relação_Calibrações_Localização!$B$8:$B$259,0))="PERDIDO",INDEX([1]Relação_Calibrações_Localização!F25:F275,MATCH(B23,[1]Relação_Calibrações_Localização!$B$8:$B$259,0))="NÃO LOCALIZADO"),"PERDIDO", IF(OR(Q23="",T23="",W23=""),"INDETERMINADO",IF(MAX(R23,U23,X23)<=5,"APROVADO","REPROVADO"))) -> APROVADO
A24: 37332230 | B24: DLH-0021 | C24: 45855 | D24: 46220 | E24: 605474 | F24: 0.2 | G24: -0.21 | H24: 0.41 | I24: -0.21 | J24: 0.41 | K24: -0.01 | L24: 0.21 | M24: -0.01 | N24: 0.21 | O24: =IF(OR(INDEX([1]Relação_Calibrações_Localização!$F$8:$F$259,MATCH(B24,[1]Relação_Calibrações_Localização!$B$8:$B$259,0))="PERDIDO",INDEX([1]Relação_Calibrações_Localização!F28:F278,MATCH(B24,[1]Relação_Calibrações_Localização!$B$8:$B$259,0))="NÃO LOCALIZADO"),"PERDIDO", IF(OR(G24="",I24="",K24="",M24=""),"INDETERMINADO",IF(MAX(H24,J24,L24,N24)<=0.5,"APROVADO","REPROVADO"))) -> APROVADO | P24: 0.4 | Q24: 3.8 | R24: 4.2 | S24: 1 | T24: 3.7 | U24: 4.7 | V24: 1.5 | W24: 1.3 | X24: 2.8 | Y24: =IF(OR(INDEX([1]Relação_Calibrações_Localização!$F$8:$F$259,MATCH(B24,[1]Relação_Calibrações_Localização!$B$8:$B$259,0))="PERDIDO",INDEX([1]Relação_Calibrações_Localização!F28:F278,MATCH(B24,[1]Relação_Calibrações_Localização!$B$8:$B$259,0))="NÃO LOCALIZADO"),"PERDIDO", IF(OR(Q24="",T24="",W24=""),"INDETERMINADO",IF(MAX(R24,U24,X24)<=5,"APROVADO","REPROVADO"))) -> APROVADO
A25: 37332232 | B25: DLH-0022 | C25: 45855 | D25: 46220 | E25: 605497 | F25: 0.2 | G25: -0.11 | H25: 0.31 | I25: -0.11 | J25: 0.31 | K25: -0.21 | L25: 0.41 | M25: -0.21 | N25: 0.41 | O25: =IF(OR(INDEX([1]Relação_Calibrações_Localização!$F$8:$F$259,MATCH(B25,[1]Relação_Calibrações_Localização!$B$8:$B$259,0))="PERDIDO",INDEX([1]Relação_Calibrações_Localização!F29:F279,MATCH(B25,[1]Relação_Calibrações_Localização!$B$8:$B$259,0))="NÃO LOCALIZADO"),"PERDIDO", IF(OR(G25="",I25="",K25="",M25=""),"INDETERMINADO",IF(MAX(H25,J25,L25,N25)<=0.5,"APROVADO","REPROVADO"))) -> APROVADO | P25: 0.4 | Q25: 3.7 | R25: 4.1 | S25: 1 | T25: 3.3 | U25: 4.3 | V25: 1.5 | W25: 1.8 | X25: 3.3 | Y25: =IF(OR(INDEX([1]Relação_Calibrações_Localização!$F$8:$F$259,MATCH(B25,[1]Relação_Calibrações_Localização!$B$8:$B$259,0))="PERDIDO",INDEX([1]Relação_Calibrações_Localização!F29:F279,MATCH(B25,[1]Relação_Calibrações_Localização!$B$8:$B$259,0))="NÃO LOCALIZADO"),"PERDIDO", IF(OR(Q25="",T25="",W25=""),"INDETERMINADO",IF(MAX(R25,U25,X25)<=5,"APROVADO","REPROVADO"))) -> APROVADO
A26: 37332240 | B26: DLH-0024 | C26: 45855 | D26: 46220 | E26: 605473 | F26: 0.2 | G26: -0.21 | H26: 0.41 | I26: -0.11 | J26: 0.31 | K26: -0.01 | L26: 0.21 | M26: 0.09 | N26: 0.29 | O26: =IF(OR(INDEX([1]Relação_Calibrações_Localização!$F$8:$F$259,MATCH(B26,[1]Relação_Calibrações_Localização!$B$8:$B$259,0))="PERDIDO",INDEX([1]Relação_Calibrações_Localização!F31:F281,MATCH(B26,[1]Relação_Calibrações_Localização!$B$8:$B$259,0))="NÃO LOCALIZADO"),"PERDIDO", IF(OR(G26="",I26="",K26="",M26=""),"INDETERMINADO",IF(MAX(H26,J26,L26,N26)<=0.5,"APROVADO","REPROVADO"))) -> APROVADO | P26: 0.4 | Q26: 4 | R26: 4.4 | S26: 1 | T26: 3.8 | U26: 4.8 | V26: 1.5 | W26: 2.4 | X26: 3.9 | Y26: =IF(OR(INDEX([1]Relação_Calibrações_Localização!$F$8:$F$259,MATCH(B26,[1]Relação_Calibrações_Localização!$B$8:$B$259,0))="PERDIDO",INDEX([1]Relação_Calibrações_Localização!F31:F281,MATCH(B26,[1]Relação_Calibrações_Localização!$B$8:$B$259,0))="NÃO LOCALIZADO"),"PERDIDO", IF(OR(Q26="",T26="",W26=""),"INDETERMINADO",IF(MAX(R26,U26,X26)<=5,"APROVADO","REPROVADO"))) -> APROVADO
A27: 37332243 | B27: DLH-0026 | C27: 45855 | D27: 46220 | E27: 605511 | F27: 0.2 | G27: -0.11 | H27: 0.31 | I27: -0.01 | J27: 0.21 | K27: 0.09 | L27: 0.29 | M27: 0.19 | N27: 0.39 | O27: =IF(OR(INDEX([1]Relação_Calibrações_Localização!$F$8:$F$259,MATCH(B27,[1]Relação_Calibrações_Localização!$B$8:$B$259,0))="PERDIDO",INDEX([1]Relação_Calibrações_Localização!F33:F283,MATCH(B27,[1]Relação_Calibrações_Localização!$B$8:$B$259,0))="NÃO LOCALIZADO"),"PERDIDO", IF(OR(G27="",I27="",K27="",M27=""),"INDETERMINADO",IF(MAX(H27,J27,L27,N27)<=0.5,"APROVADO","REPROVADO"))) -> APROVADO | P27: 0.4 | Q27: 3.2 | R27: 3.6 | S27: 1 | T27: 2.8 | U27: 3.8 | V27: 1.5 | W27: 2.3 | X27: 3.8 | Y27: =IF(OR(INDEX([1]Relação_Calibrações_Localização!$F$8:$F$259,MATCH(B27,[1]Relação_Calibrações_Localização!$B$8:$B$259,0))="PERDIDO",INDEX([1]Relação_Calibrações_Localização!F33:F283,MATCH(B27,[1]Relação_Calibrações_Localização!$B$8:$B$259,0))="NÃO LOCALIZADO"),"PERDIDO", IF(OR(Q27="",T27="",W27=""),"INDETERMINADO",IF(MAX(R27,U27,X27)<=5,"APROVADO","REPROVADO"))) -> APROVADO
A28: 37332270 | B28: DLH-0027 | C28: 45855 | D28: 46220 | E28: 605456 | F28: 0.2 | G28: -0.01 | H28: 0.21 | I28: -0.01 | J28: 0.21 | K28: 0.09 | L28: 0.29 | M28: 0.19 | N28: 0.39 | O28: =IF(OR(INDEX([1]Relação_Calibrações_Localização!$F$8:$F$259,MATCH(B28,[1]Relação_Calibrações_Localização!$B$8:$B$259,0))="PERDIDO",INDEX([1]Relação_Calibrações_Localização!F34:F284,MATCH(B28,[1]Relação_Calibrações_Localização!$B$8:$B$259,0))="NÃO LOCALIZADO"),"PERDIDO", IF(OR(G28="",I28="",K28="",M28=""),"INDETERMINADO",IF(MAX(H28,J28,L28,N28)<=0.5,"APROVADO","REPROVADO"))) -> APROVADO | P28: 0.4 | Q28: 3.5 | R28: 3.9 | S28: 1 | T28: 3 | U28: 4 | V28: 1.5 | W28: 1.3 | X28: 2.8 | Y28: =IF(OR(INDEX([1]Relação_Calibrações_Localização!$F$8:$F$259,MATCH(B28,[1]Relação_Calibrações_Localização!$B$8:$B$259,0))="PERDIDO",INDEX([1]Relação_Calibrações_Localização!F34:F284,MATCH(B28,[1]Relação_Calibrações_Localização!$B$8:$B$259,0))="NÃO LOCALIZADO"),"PERDIDO", IF(OR(Q28="",T28="",W28=""),"INDETERMINADO",IF(MAX(R28,U28,X28)<=5,"APROVADO","REPROVADO"))) -> APROVADO
A29: 37332283 | B29: DLH-0030 | C29: 45855 | D29: 46220 | E29: 605471 | F29: 0.2 | G29: 0.09 | H29: 0.29 | I29: -0.01 | J29: 0.21 | K29: -0.11 | L29: 0.31 | M29: -0.21 | N29: 0.41 | O29: =IF(OR(INDEX([1]Relação_Calibrações_Localização!$F$8:$F$259,MATCH(B29,[1]Relação_Calibrações_Localização!$B$8:$B$259,0))="PERDIDO",INDEX([1]Relação_Calibrações_Localização!F37:F287,MATCH(B29,[1]Relação_Calibrações_Localização!$B$8:$B$259,0))="NÃO LOCALIZADO"),"PERDIDO", IF(OR(G29="",I29="",K29="",M29=""),"INDETERMINADO",IF(MAX(H29,J29,L29,N29)<=0.5,"APROVADO","REPROVADO"))) -> APROVADO | P29: 0.4 | Q29: 3.2 | R29: 3.6 | S29: 1 | T29: 2.8 | U29: 3.8 | V29: 1.5 | W29: 2 | X29: 3.5 | Y29: =IF(OR(INDEX([1]Relação_Calibrações_Localização!$F$8:$F$259,MATCH(B29,[1]Relação_Calibrações_Localização!$B$8:$B$259,0))="PERDIDO",INDEX([1]Relação_Calibrações_Localização!F37:F287,MATCH(B29,[1]Relação_Calibrações_Localização!$B$8:$B$259,0))="NÃO LOCALIZADO"),"PERDIDO", IF(OR(Q29="",T29="",W29=""),"INDETERMINADO",IF(MAX(R29,U29,X29)<=5,"APROVADO","REPROVADO"))) -> APROVADO
A30: 37332436 | B30: DLH-0032 | C30: 45855 | D30: 46220 | E30: 605460 | F30: 0.2 | G30: 0.09 | H30: 0.29 | I30: 0.09 | J30: 0.29 | K30: -0.11 | L30: 0.31 | M30: -0.21 | N30: 0.41 | O30: APROVADO | P30: 0.4 | Q30: 3.2 | R30: 3.6 | S30: 1 | T30: 2.7 | U30: 3.7 | V30: 1.5 | W30: 0.3 | X30: 1.8 | Y30: =IF(OR(INDEX([1]Relação_Calibrações_Localização!$F$8:$F$259,MATCH(B30,[1]Relação_Calibrações_Localização!$B$8:$B$259,0))="PERDIDO",INDEX([1]Relação_Calibrações_Localização!F39:F289,MATCH(B30,[1]Relação_Calibrações_Localização!$B$8:$B$259,0))="NÃO LOCALIZADO"),"PERDIDO", IF(OR(Q30="",T30="",W30=""),"INDETERMINADO",IF(MAX(R30,U30,X30)<=5,"APROVADO","REPROVADO"))) -> APROVADO
A31: 37332465 | B31: DLH-0035 | C31: 45855 | D31: 46220 | E31: 605510 | F31: 0.2 | G31: 0.09 | H31: 0.29 | I31: -0.11 | J31: 0.31 | K31: -0.11 | L31: 0.31 | M31: -0.21 | N31: 0.41 | O31: =IF(OR(INDEX([1]Relação_Calibrações_Localização!$F$8:$F$259,MATCH(B31,[1]Relação_Calibrações_Localização!$B$8:$B$259,0))="PERDIDO",INDEX([1]Relação_Calibrações_Localização!F42:F292,MATCH(B31,[1]Relação_Calibrações_Localização!$B$8:$B$259,0))="NÃO LOCALIZADO"),"PERDIDO", IF(OR(G31="",I31="",K31="",M31=""),"INDETERMINADO",IF(MAX(H31,J31,L31,N31)<=0.5,"APROVADO","REPROVADO"))) -> APROVADO | P31: 0.4 | Q31: 1.7 | R31: 2.1 | S31: 1 | T31: 0.5 | U31: 1.5 | V31: 1.5 | W31: -0.6 | X31: 2.1 | Y31: =IF(OR(INDEX([1]Relação_Calibrações_Localização!$F$8:$F$259,MATCH(B31,[1]Relação_Calibrações_Localização!$B$8:$B$259,0))="PERDIDO",INDEX([1]Relação_Calibrações_Localização!F42:F292,MATCH(B31,[1]Relação_Calibrações_Localização!$B$8:$B$259,0))="NÃO LOCALIZADO"),"PERDIDO", IF(OR(Q31="",T31="",W31=""),"INDETERMINADO",IF(MAX(R31,U31,X31)<=5,"APROVADO","REPROVADO"))) -> APROVADO
A32: 37332470 | B32: DLH-0037 | C32: 45855 | D32: 46220 | E32: 605425 | F32: 0.2 | G32: -0.21 | H32: 0.41 | I32: -0.11 | J32: 0.31 | K32: -0.11 | L32: 0.31 | M32: 0.09 | N32: 0.29 | O32: =IF(OR(INDEX([1]Relação_Calibrações_Localização!$F$8:$F$259,MATCH(B32,[1]Relação_Calibrações_Localização!$B$8:$B$259,0))="PERDIDO",INDEX([1]Relação_Calibrações_Localização!F44:F294,MATCH(B32,[1]Relação_Calibrações_Localização!$B$8:$B$259,0))="NÃO LOCALIZADO"),"PERDIDO", IF(OR(G32="",I32="",K32="",M32=""),"INDETERMINADO",IF(MAX(H32,J32,L32,N32)<=0.5,"APROVADO","REPROVADO"))) -> APROVADO | P32: 0.4 | Q32: 3.3 | R32: 3.7 | S32: 1 | T32: 2 | U32: 3 | V32: 1.5 | W32: 1.3 | X32: 2.8 | Y32: =IF(OR(INDEX([1]Relação_Calibrações_Localização!$F$8:$F$259,MATCH(B32,[1]Relação_Calibrações_Localização!$B$8:$B$259,0))="PERDIDO",INDEX([1]Relação_Calibrações_Localização!F44:F294,MATCH(B32,[1]Relação_Calibrações_Localização!$B$8:$B$259,0))="NÃO LOCALIZADO"),"PERDIDO", IF(OR(Q32="",T32="",W32=""),"INDETERMINADO",IF(MAX(R32,U32,X32)<=5,"APROVADO","REPROVADO"))) -> APROVADO
A33: 37332476 | B33: DLH-0039 | C33: 45855 | D33: 46220 | E33: 605550 | F33: 0.2 | G33: -0.21 | H33: 0.41 | I33: -0.01 | J33: 0.21 | K33: -0.01 | L33: 0.21 | M33: 0.09 | N33: 0.29 | O33: =IF(OR(INDEX([1]Relação_Calibrações_Localização!$F$8:$F$259,MATCH(B33,[1]Relação_Calibrações_Localização!$B$8:$B$259,0))="PERDIDO",INDEX([1]Relação_Calibrações_Localização!F46:F296,MATCH(B33,[1]Relação_Calibrações_Localização!$B$8:$B$259,0))="NÃO LOCALIZADO"),"PERDIDO", IF(OR(G33="",I33="",K33="",M33=""),"INDETERMINADO",IF(MAX(H33,J33,L33,N33)<=0.5,"APROVADO","REPROVADO"))) -> APROVADO | P33: 0.4 | Q33: 2.2 | R33: 2.6 | S33: 1 | T33: 0 | U33: 1 | V33: 1.5 | W33: -0.3 | X33: 1.8 | Y33: =IF(OR(INDEX([1]Relação_Calibrações_Localização!$F$8:$F$259,MATCH(B33,[1]Relação_Calibrações_Localização!$B$8:$B$259,0))="PERDIDO",INDEX([1]Relação_Calibrações_Localização!F46:F296,MATCH(B33,[1]Relação_Calibrações_Localização!$B$8:$B$259,0))="NÃO LOCALIZADO"),"PERDIDO", IF(OR(Q33="",T33="",W33=""),"INDETERMINADO",IF(MAX(R33,U33,X33)<=5,"APROVADO","REPROVADO"))) -> APROVADO
A34: 37332477 | B34: DLH-0040 | C34: 45855 | D34: 46220 | E34: 605493 | F34: 0.2 | G34: -0.11 | H34: 0.31 | I34: -0.11 | J34: 0.31 | K34: -0.01 | L34: 0.21 | M34: 0.19 | N34: 0.39 | O34: =IF(OR(INDEX([1]Relação_Calibrações_Localização!$F$8:$F$259,MATCH(B34,[1]Relação_Calibrações_Localização!$B$8:$B$259,0))="PERDIDO",INDEX([1]Relação_Calibrações_Localização!F47:F297,MATCH(B34,[1]Relação_Calibrações_Localização!$B$8:$B$259,0))="NÃO LOCALIZADO"),"PERDIDO", IF(OR(G34="",I34="",K34="",M34=""),"INDETERMINADO",IF(MAX(H34,J34,L34,N34)<=0.5,"APROVADO","REPROVADO"))) -> APROVADO | P34: 0.4 | Q34: 3.7 | R34: 4.1 | S34: 1 | T34: 3.6 | U34: 4.6 | V34: 1.5 | W34: 3.3 | X34: 4.8 | Y34: =IF(OR(INDEX([1]Relação_Calibrações_Localização!$F$8:$F$259,MATCH(B34,[1]Relação_Calibrações_Localização!$B$8:$B$259,0))="PERDIDO",INDEX([1]Relação_Calibrações_Localização!F47:F297,MATCH(B34,[1]Relação_Calibrações_Localização!$B$8:$B$259,0))="NÃO LOCALIZADO"),"PERDIDO", IF(OR(Q34="",T34="",W34=""),"INDETERMINADO",IF(MAX(R34,U34,X34)<=5,"APROVADO","REPROVADO"))) -> APROVADO
A35: 37332478 | B35: DLH-0041 | C35: 45855 | D35: 46220 | E35: 605435 | F35: 0.2 | G35: -0.11 | H35: 0.31 | I35: -0.01 | J35: 0.21 | K35: 0.09 | L35: 0.29 | M35: 0.19 | N35: 0.39 | O35: =IF(OR(INDEX([1]Relação_Calibrações_Localização!$F$8:$F$259,MATCH(B35,[1]Relação_Calibrações_Localização!$B$8:$B$259,0))="PERDIDO",INDEX([1]Relação_Calibrações_Localização!F48:F298,MATCH(B35,[1]Relação_Calibrações_Localização!$B$8:$B$259,0))="NÃO LOCALIZADO"),"PERDIDO", IF(OR(G35="",I35="",K35="",M35=""),"INDETERMINADO",IF(MAX(H35,J35,L35,N35)<=0.5,"APROVADO","REPROVADO"))) -> APROVADO | P35: 0.4 | Q35: 3.4 | R35: 3.8 | S35: 1 | T35: 3.3 | U35: 4.3 | V35: 1.5 | W35: 1.5 | X35: 3 | Y35: =IF(OR(INDEX([1]Relação_Calibrações_Localização!$F$8:$F$259,MATCH(B35,[1]Relação_Calibrações_Localização!$B$8:$B$259,0))="PERDIDO",INDEX([1]Relação_Calibrações_Localização!F48:F298,MATCH(B35,[1]Relação_Calibrações_Localização!$B$8:$B$259,0))="NÃO LOCALIZADO"),"PERDIDO", IF(OR(Q35="",T35="",W35=""),"INDETERMINADO",IF(MAX(R35,U35,X35)<=5,"APROVADO","REPROVADO"))) -> APROVADO
A36: 37332492 | B36: DLH-0044 | C36: 45855 | D36: 46220 | E36: 605429 | F36: 0.2 | G36: -0.11 | H36: 0.31 | I36: -0.01 | J36: 0.21 | K36: 0.09 | L36: 0.29 | M36: 0.09 | N36: 0.29 | O36: =IF(OR(INDEX([1]Relação_Calibrações_Localização!$F$8:$F$259,MATCH(B36,[1]Relação_Calibrações_Localização!$B$8:$B$259,0))="PERDIDO",INDEX([1]Relação_Calibrações_Localização!F51:F301,MATCH(B36,[1]Relação_Calibrações_Localização!$B$8:$B$259,0))="NÃO LOCALIZADO"),"PERDIDO", IF(OR(G36="",I36="",K36="",M36=""),"INDETERMINADO",IF(MAX(H36,J36,L36,N36)<=0.5,"APROVADO","REPROVADO"))) -> APROVADO | P36: 0.4 | Q36: 3.8 | R36: 4.2 | S36: 1 | T36: 3.6 | U36: 4.6 | V36: 1.5 | W36: 3.4 | X36: 4.9 | Y36: =IF(OR(INDEX([1]Relação_Calibrações_Localização!$F$8:$F$259,MATCH(B36,[1]Relação_Calibrações_Localização!$B$8:$B$259,0))="PERDIDO",INDEX([1]Relação_Calibrações_Localização!F51:F301,MATCH(B36,[1]Relação_Calibrações_Localização!$B$8:$B$259,0))="NÃO LOCALIZADO"),"PERDIDO", IF(OR(Q36="",T36="",W36=""),"INDETERMINADO",IF(MAX(R36,U36,X36)<=5,"APROVADO","REPROVADO"))) -> APROVADO
A37: 37332723 | B37: DLH-0045 | C37: 45855 | D37: 46220 | E37: 605547 | F37: 0.2 | G37: -0.21 | H37: 0.41 | I37: -0.11 | J37: 0.31 | K37: -0.11 | L37: 0.31 | M37: -0.01 | N37: 0.21 | O37: =IF(OR(INDEX([1]Relação_Calibrações_Localização!$F$8:$F$259,MATCH(B37,[1]Relação_Calibrações_Localização!$B$8:$B$259,0))="PERDIDO",INDEX([1]Relação_Calibrações_Localização!F52:F302,MATCH(B37,[1]Relação_Calibrações_Localização!$B$8:$B$259,0))="NÃO LOCALIZADO"),"PERDIDO", IF(OR(G37="",I37="",K37="",M37=""),"INDETERMINADO",IF(MAX(H37,J37,L37,N37)<=0.5,"APROVADO","REPROVADO"))) -> APROVADO | P37: 0.4 | Q37: 2.8 | R37: 3.2 | S37: 1 | T37: 2.1 | U37: 3.1 | V37: 1.5 | W37: 2.1 | X37: 3.6 | Y37: =IF(OR(INDEX([1]Relação_Calibrações_Localização!$F$8:$F$259,MATCH(B37,[1]Relação_Calibrações_Localização!$B$8:$B$259,0))="PERDIDO",INDEX([1]Relação_Calibrações_Localização!F52:F302,MATCH(B37,[1]Relação_Calibrações_Localização!$B$8:$B$259,0))="NÃO LOCALIZADO"),"PERDIDO", IF(OR(Q37="",T37="",W37=""),"INDETERMINADO",IF(MAX(R37,U37,X37)<=5,"APROVADO","REPROVADO"))) -> APROVADO
A38: 37333128 | B38: DLH-0047 | C38: 45855 | D38: 46220 | E38: 605466 | F38: 0.2 | G38: -0.21 | H38: 0.41 | I38: -0.11 | J38: 0.31 | K38: 0.09 | L38: 0.29 | M38: 0.09 | N38: 0.29 | O38: =IF(OR(INDEX([1]Relação_Calibrações_Localização!$F$8:$F$259,MATCH(B38,[1]Relação_Calibrações_Localização!$B$8:$B$259,0))="PERDIDO",INDEX([1]Relação_Calibrações_Localização!F54:F304,MATCH(B38,[1]Relação_Calibrações_Localização!$B$8:$B$259,0))="NÃO LOCALIZADO"),"PERDIDO", IF(OR(G38="",I38="",K38="",M38=""),"INDETERMINADO",IF(MAX(H38,J38,L38,N38)<=0.5,"APROVADO","REPROVADO"))) -> APROVADO | P38: 0.4 | Q38: 3.6 | R38: 4 | S38: 1 | T38: 3.6 | U38: 4.6 | V38: 1.5 | W38: 1.4 | X38: 2.9 | Y38: =IF(OR(INDEX([1]Relação_Calibrações_Localização!$F$8:$F$259,MATCH(B38,[1]Relação_Calibrações_Localização!$B$8:$B$259,0))="PERDIDO",INDEX([1]Relação_Calibrações_Localização!F54:F304,MATCH(B38,[1]Relação_Calibrações_Localização!$B$8:$B$259,0))="NÃO LOCALIZADO"),"PERDIDO", IF(OR(Q38="",T38="",W38=""),"INDETERMINADO",IF(MAX(R38,U38,X38)<=5,"APROVADO","REPROVADO"))) -> APROVADO
A39: 37333129 | B39: DLH-0048 | C39: 45855 | D39: 46220 | E39: 605556 | F39: 0.2 | G39: 0.29 | H39: 0.49 | I39: 0.19 | J39: 0.39 | K39: 0.19 | L39: 0.39 | M39: 0.09 | N39: 0.29 | O39: =IF(OR(INDEX([1]Relação_Calibrações_Localização!$F$8:$F$259,MATCH(B39,[1]Relação_Calibrações_Localização!$B$8:$B$259,0))="PERDIDO",INDEX([1]Relação_Calibrações_Localização!F55:F305,MATCH(B39,[1]Relação_Calibrações_Localização!$B$8:$B$259,0))="NÃO LOCALIZADO"),"PERDIDO", IF(OR(G39="",I39="",K39="",M39=""),"INDETERMINADO",IF(MAX(H39,J39,L39,N39)<=0.5,"APROVADO","REPROVADO"))) -> APROVADO | P39: 0.4 | Q39: 3.1 | R39: 3.5 | S39: 1 | T39: 2.3 | U39: 3.3 | V39: 1.5 | W39: 1.5 | X39: 3 | Y39: =IF(OR(INDEX([1]Relação_Calibrações_Localização!$F$8:$F$259,MATCH(B39,[1]Relação_Calibrações_Localização!$B$8:$B$259,0))="PERDIDO",INDEX([1]Relação_Calibrações_Localização!F55:F305,MATCH(B39,[1]Relação_Calibrações_Localização!$B$8:$B$259,0))="NÃO LOCALIZADO"),"PERDIDO", IF(OR(Q39="",T39="",W39=""),"INDETERMINADO",IF(MAX(R39,U39,X39)<=5,"APROVADO","REPROVADO"))) -> APROVADO
A40: 37333131 | B40: DLH-0049 | C40: 45855 | D40: 46220 | E40: 605518 | F40: 0.2 | G40: 0.29 | H40: 0.49 | I40: 0.19 | J40: 0.39 | K40: 0.19 | L40: 0.39 | M40: -0.01 | N40: 0.21 | O40: =IF(OR(INDEX([1]Relação_Calibrações_Localização!$F$8:$F$259,MATCH(B40,[1]Relação_Calibrações_Localização!$B$8:$B$259,0))="PERDIDO",INDEX([1]Relação_Calibrações_Localização!F56:F306,MATCH(B40,[1]Relação_Calibrações_Localização!$B$8:$B$259,0))="NÃO LOCALIZADO"),"PERDIDO", IF(OR(G40="",I40="",K40="",M40=""),"INDETERMINADO",IF(MAX(H40,J40,L40,N40)<=0.5,"APROVADO","REPROVADO"))) -> APROVADO | P40: 0.4 | Q40: 2.8 | R40: 3.2 | S40: 1 | T40: -0.6 | U40: 1.6 | V40: 1.5 | W40: 1.7 | X40: 3.2 | Y40: =IF(OR(INDEX([1]Relação_Calibrações_Localização!$F$8:$F$259,MATCH(B40,[1]Relação_Calibrações_Localização!$B$8:$B$259,0))="PERDIDO",INDEX([1]Relação_Calibrações_Localização!F56:F306,MATCH(B40,[1]Relação_Calibrações_Localização!$B$8:$B$259,0))="NÃO LOCALIZADO"),"PERDIDO", IF(OR(Q40="",T40="",W40=""),"INDETERMINADO",IF(MAX(R40,U40,X40)<=5,"APROVADO","REPROVADO"))) -> APROVADO
A41: 37333137 | B41: DLH-0050 | C41: 45855 | D41: 46220 | E41: 605523 | F41: 0.2 | G41: 0.09 | H41: 0.29 | I41: -0.01 | J41: 0.21 | K41: -0.01 | L41: 0.21 | M41: 0.19 | N41: 0.39 | O41: =IF(OR(INDEX([1]Relação_Calibrações_Localização!$F$8:$F$259,MATCH(B41,[1]Relação_Calibrações_Localização!$B$8:$B$259,0))="PERDIDO",INDEX([1]Relação_Calibrações_Localização!F57:F307,MATCH(B41,[1]Relação_Calibrações_Localização!$B$8:$B$259,0))="NÃO LOCALIZADO"),"PERDIDO", IF(OR(G41="",I41="",K41="",M41=""),"INDETERMINADO",IF(MAX(H41,J41,L41,N41)<=0.5,"APROVADO","REPROVADO"))) -> APROVADO | P41: 0.4 | Q41: 2.9 | R41: 3.3 | S41: 1 | T41: 3 | U41: 4 | V41: 1.5 | W41: 1.7 | X41: 3.2 | Y41: =IF(OR(INDEX([1]Relação_Calibrações_Localização!$F$8:$F$259,MATCH(B41,[1]Relação_Calibrações_Localização!$B$8:$B$259,0))="PERDIDO",INDEX([1]Relação_Calibrações_Localização!F57:F307,MATCH(B41,[1]Relação_Calibrações_Localização!$B$8:$B$259,0))="NÃO LOCALIZADO"),"PERDIDO", IF(OR(Q41="",T41="",W41=""),"INDETERMINADO",IF(MAX(R41,U41,X41)<=5,"APROVADO","REPROVADO"))) -> APROVADO
A42: 37333139 | B42: DLH-0051 | C42: 45855 | D42: 46220 | E42: 605446 | F42: 0.2 | G42: -0.01 | H42: 0.21 | I42: 0.09 | J42: 0.29 | K42: 0.19 | L42: 0.39 | M42: 0.19 | N42: 0.39 | O42: =IF(OR(INDEX([1]Relação_Calibrações_Localização!$F$8:$F$259,MATCH(B42,[1]Relação_Calibrações_Localização!$B$8:$B$259,0))="PERDIDO",INDEX([1]Relação_Calibrações_Localização!F58:F308,MATCH(B42,[1]Relação_Calibrações_Localização!$B$8:$B$259,0))="NÃO LOCALIZADO"),"PERDIDO", IF(OR(G42="",I42="",K42="",M42=""),"INDETERMINADO",IF(MAX(H42,J42,L42,N42)<=0.5,"APROVADO","REPROVADO"))) -> APROVADO | P42: 0.4 | Q42: 2.6 | R42: 3 | S42: 1 | T42: 2.3 | U42: 3.3 | V42: 1.5 | W42: 1.5 | X42: 3 | Y42: =IF(OR(INDEX([1]Relação_Calibrações_Localização!$F$8:$F$259,MATCH(B42,[1]Relação_Calibrações_Localização!$B$8:$B$259,0))="PERDIDO",INDEX([1]Relação_Calibrações_Localização!F58:F308,MATCH(B42,[1]Relação_Calibrações_Localização!$B$8:$B$259,0))="NÃO LOCALIZADO"),"PERDIDO", IF(OR(Q42="",T42="",W42=""),"INDETERMINADO",IF(MAX(R42,U42,X42)<=5,"APROVADO","REPROVADO"))) -> APROVADO
...
